Workbook

Sheet 제품별 광고비 현황(24.01~26.01)
B2: 코렐브랜드 - 광고비 집행 현황 (2024.01 ~ 2026.01)
B4: [자료 출처]
B6: - 리서치애드 https://www.researchad.com / ADEX
B7: - 데이터 기간: 2024.01.01 ~ 2026.01.31
B8: - 브랜드: 코렐브랜드, 락앤락, 글라스락, 이케아
B9: [Comment]
B11: - 2024년 1월~2026년 1월 기간 내 총 광고비 4,108,828천원 집계되었습니다.
B12: - 전체 기간 광고비 지출이 높은 브랜드는 '이케아 2,090,243천원 > 락앤락 1,315,066천원 > 글라스락 649,763천원 > 코렐브랜드 53,756천원…' 순이었습니다.
B13: - 대부분의 브랜드에서 디지털 영상 카테고리 지출이 가장 높았습니다.
B15: 브랜드별 집행 광고비 | D15: (단위: 천 원) | F15: 브랜드별 연도별 집행 광고비 | I15: (단위: 천 원)
B38: 브랜드별 집행 광고비 현황
C39: 2025년 11월 | E39: 2026년 1월
B40: 합계 : 광고비(천원) | C40: 열 레이블
C41: 2024년 | O41: 2024년 요약 | P41: 2025년 | AB41: 2025년 요약 | AC41: 2026년 | AD41: 2026년 요약 | AE41: 총 합계
B42: 브랜드 | C42: 1월 | D42: 2월 | E42: 3월 | F42: 4월 | G42: 5월 | H42: 6월 | I42: 7월 | J42: 8월 | K42: 9월 | L42: 10월 | M42: 11월 | N42: 12월 | P42: 1월 | Q42: 2월 | R42: 3월 | S42: 4월 | T42: 5월 | U42: 6월 | V42: 7월 | W42: 8월 | X42: 9월 | Y42: 10월 | Z42: 11월 | AA42: 12월 | AC42: 1월
B43: 이케아코리아 | C43: 39383 | D43: 27881 | E43: 24258 | F43: 22299 | G43: 280755 | H43: 57791 | I43: 45818 | J43: 79414 | K43: 12018 | L43: 10927 | N43: 8765 | O43: 609309 | P43: 237000 | Q43: 193290 | R43: 68208 | S43: 12654 | T43: 19242 | U43: 48811 | V43: 33004 | W43: 119172 | X43: 190126 | Y43: 281048 | Z43: 252404 | AA43: 24402 | AB43: 1479361 | AC43: 1573 | AD43: 1573 | AE43: 2090243
B44: 디지털 영상 | G44: 30836 | H44: 25211 | I44: 15416 | J44: 1065 | K44: 12018 | N44: 8765 | O44: 93311 | P44: 233061 | Q44: 100817 | R44: 22205 | S44: 78 | T44: 11049 | U44: 753 | W44: 14455 | X44: 97276 | Y44: 174806 | Z44: 132159 | AA44: 1448 | AB44: 788107 | AE44: 881418
B45: 네트워크 | C45: 26910 | D45: 26223 | E45: 21067 | F45: 19707 | G45: 175932 | H45: 32580 | I45: 26064 | L45: 8736 | O45: 337219 | P45: 3939 | Q45: 43194 | R45: 46003 | S45: 4659 | T45: 8193 | V45: 33004 | W45: 104717 | X45: 90286 | Y45: 1359 | Z45: 8807 | AA45: 19123 | AB45: 363284 | AC45: 1573 | AD45: 1573 | AE45: 702076
B46: 포털 | C46: 10814 | E46: 2193 | F46: 2193 | G46: 69472 | I46: 4338 | J46: 78349 | L46: 2191 | O46: 169550 | Q46: 46823 | S46: 5094 | U46: 48058 | Y46: 104883 | Z46: 111438 | AB46: 316296 | AE46: 485846
B47: SNS | C47: 1659 | D47: 1658 | E47: 998 | F47: 399 | G47: 4515 | O47: 9229 | Q47: 2456 | S47: 2823 | X47: 2564 | AA47: 3831 | AB47: 11674 | AE47: 20903
B48: 락앤락 | D48: 820 | E48: 221 | G48: 102736 | H48: 140338 | I48: 21491 | J48: 11351 | K48: 17976 | L48: 25858 | M48: 66 | O48: 320857 | P48: 125 | Q48: 61404 | R48: 29571 | T48: 31664 | U48: 88807 | V48: 195037 | W48: 86356 | X48: 282738 | Y48: 209777 | Z48: 6982 | AB48: 992461 | AC48: 1748 | AD48: 1748 | AE48: 1315066
B49: 디지털 영상 | G49: 89642 | H49: 133822 | I49: 21439 | J49: 505 | K49: 17914 | L49: 2725 | O49: 266047 | U49: 3096 | V49: 17028 | W49: 4415 | X49: 250276 | Y49: 150082 | AB49: 424897 | AE49: 690944
B50: 포털 | J50: 10846 | L50: 23133 | O50: 33979 | T50: 30655 | U50: 73570 | V50: 177795 | W50: 81941 | AB50: 363961 | AC50: 31 | AD50: 31 | AE50: 397971
B51: 네트워크 | D51: 820 | E51: 159 | G51: 13032 | H51: 6516 | I51: 52 | M51: 66 | O51: 20645 | P51: 63 | Q51: 58948 | R51: 29571 | T51: 947 | U51: 12141 | V51: 214 | X51: 32462 | Y51: 59695 | Z51: 1814 | AB51: 195855 | AE51: 216500
B52: SNS | E52: 62 | G52: 62 | K52: 62 | O52: 186 | P52: 62 | Q52: 2456 | T52: 62 | Z52: 5168 | AB52: 7748 | AC52: 1717 | AD52: 1717 | AE52: 9651
B53: 글라스락 | E53: 5266 | F53: 62 | H53: 136823 | I53: 81592 | J53: 97670 | K53: 108615 | L53: 105275 | M53: 52110 | O53: 587413 | P53: 8149 | Q53: 8102 | S53: 62 | T53: 8576 | U53: 10811 | V53: 6356 | W53: 600 | X53: 1415 | Y53: 3277 | Z53: 3542 | AA53: 3116 | AB53: 54006 | AC53: 8344 | AD53: 8344 | AE53: 649763
B54: 디지털 영상 | H54: 136164 | I54: 81592 | J54: 97484 | K54: 108615 | L54: 105275 | M54: 52110 | O54: 581240 | P54: 8149 | Q54: 6465 | T54: 8576 | AB54: 23190 | AE54: 604430
B55: SNS | E55: 1198 | F55: 62 | O55: 1260 | Q55: 1637 | S55: 62 | U55: 10651 | V55: 5606 | AB55: 17956 | AE55: 19216
B56: 네트워크 | E56: 4068 | H56: 659 | O56: 4727 | U56: 160 | V56: 750 | W56: 450 | X56: 1415 | Y56: 2781 | Z56: 3294 | AA56: 2620 | AB56: 11470 | AC56: 1341 | AD56: 1341 | AE56: 17538
B57: 포털 | J57: 186 | O57: 186 | W57: 150 | Y57: 496 | Z57: 248 | AA57: 496 | AB57: 1390 | AC57: 7003 | AD57: 7003 | AE57: 8579
B58: 코렐브랜드 | C58: 182 | D58: 1132 | E58: 1909 | F58: 728 | G58: 390 | H58: 390 | I58: 1904 | J58: 4174 | K58: 525 | L58: 495 | M58: 734 | N58: 6614 | O58: 19177 | P58: 2702 | Q58: 2456 | R58: 3274 | S58: 5243 | Z58: 7661 | AA58: 132 | AB58: 21468 | AC58: 13111 | AD58: 13111 | AE58: 53756
B59: SNS | D59: 131 | J59: 2791 | M59: 734 | N59: 6614 | O59: 10270 | P59: 2702 | Q59: 2456 | R59: 3274 | S59: 5243 | Z59: 7661 | AB59: 21336 | AE59: 31606
B60: 포털 | AC60: 13111 | AD60: 13111 | AE60: 13111
B61: 네트워크 | C61: 182 | D61: 1001 | E61: 1909 | F61: 728 | G61: 390 | H61: 390 | I61: 1904 | J61: 1383 | K61: 525 | L61: 495 | O61: 8907 | AA61: 132 | AB61: 132 | AE61: 9039
B62: 총 합계 | C62: 39565 | D62: 29833 | E62: 31654 | F62: 23089 | G62: 383881 | H62: 335342 | I62: 150805 | J62: 192609 | K62: 139134 | L62: 142555 | M62: 52910 | N62: 15379 | O62: 1536756 | P62: 247976 | Q62: 265252 | R62: 101053 | S62: 17959 | T62: 59482 | U62: 148429 | V62: 234397 | W62: 206128 | X62: 474279 | Y62: 494102 | Z62: 270589 | AA62: 27650 | AB62: 2547296 | AC62: 24776 | AD62: 24776 | AE62: 4108828
K63: Total | L63: =SUM(L60:L62) -> 143050 | M63: =SUM(M60:M62) -> 52910 | N63: =SUM(N60:N62) -> 15379 | O63: =SUM(O60:O62) -> 1545663
D149: 25년 1분기 | E149: 25년 2분기 | F149: 25년 3분기 | G149: 25년 4분기
C150: 푸라닭 | D150: =SUM($C43:$E43) -> 91522 | E150: =SUM($F43:$L43) -> 509022 | F150: =SUM($M43:$N43) -> 8765 | G150: =SUM($O43:$P43) -> 846309
C151: 60계치킨 | D151: =SUM($C50:$E50) -> 0 | E151: =SUM($F50:$H50) -> 0 | F151: =SUM($I50:$K50) -> 10846 | G151: =SUM($L50:$N50) -> 23133
C152: 자담치킨 | D152: =SUM(#REF!) -> #REF! | E152: =SUM(#REF!) -> #REF! | F152: =SUM(#REF!) -> #REF! | G152: =SUM(#REF!) -> #REF!
...

Sheet 광고주별
A3: 행 레이블 | B3: 합계 : 광고비(천원)
A4: 드리미 | B4: 1736626
A5: 로보락 | B5: 1714246
A6: 삼성전자 | B6: 194769
A7: LG전자 | B7: 188423
A8: 쿠쿠전자 | B8: 70419
A9: (비어 있음)
A10: 총합계 | B10: 3904483

Sheet 월별
A3: 합계 : 광고비(천원) | B3: 열 레이블
A4: 행 레이블 | B4: 드리미 | C4: 로보락 | D4: 삼성전자 | E4: LG전자 | F4: 쿠쿠전자 | G4: (비어 있음) | H4: 총합계
A6: 01 | B6: 1154378 | C6: 212824 | E6: 32456 | F6: 19237 | H6: 1418895
A7: 02 | B7: 296426 | C7: 406629 | E7: 132143 | F7: 4347 | H7: 839545
A8: 03 | B8: 52444 | C8: 487046 | E8: 16102 | F8: 11925 | H8: 567517
A9: 04 | B9: 101411 | C9: 484811 | D9: 156439 | F9: 34910 | H9: 777571
A10: 05 | B10: 131967 | C10: 122936 | D10: 38330 | E10: 7722 | H10: 300955
A11: 총합계 | B11: 1736626 | C11: 1714246 | D11: 194769 | E11: 188423 | F11: 70419 | H11: 3904483

Sheet 매체 카테고리별 광고비 현황(24.01~26.01)
B2: 코렐브랜드 - 광고비 집행 현황 (2024.01 ~ 2026.01)
B4: [자료 출처]
B6: - 리서치애드 https://www.researchad.com / ADEX
B7: - 데이터 기간: 2024.01.01 ~ 2026.01.31
B8: - 브랜드: 코렐브랜드, 락앤락, 글라스락, 이케아
B9: [Comment]
B11: - 2024년 1월~2026년 1월 기간 내 총 광고비 4,108,828천원 집계되었습니다.
B12: - 전체 기간 광고비 지출이 높은 매체 카테고리는 '디지털영상 2,176,792천원 > 네트워크 945,153천원 > 포털 905,507천원 > SNS 81,376천원…' 순이었습니다.
B14: 매체카테고리별 집행 광고비 | D14: (단위: 천 원) | F14: 매체 카테고리별 연도별 집행 광고비 | I14: (단위: 천 원)
B37: 매체 카테고리별 광고비 현황
C38: 2025년 11월 | E38: 2026년 1월
B39: 합계 : 광고비(천원) | C39: 열 레이블
C40: 2024년 | O40: 2024년 요약 | P40: 2025년 | AB40: 2025년 요약 | AC40: 2026년 | AD40: 2026년 요약 | AE40: 총 합계
B41: 매체 카테고리 | C41: 1월 | D41: 2월 | E41: 3월 | F41: 4월 | G41: 5월 | H41: 6월 | I41: 7월 | J41: 8월 | K41: 9월 | L41: 10월 | M41: 11월 | N41: 12월 | P41: 1월 | Q41: 2월 | R41: 3월 | S41: 4월 | T41: 5월 | U41: 6월 | V41: 7월 | W41: 8월 | X41: 9월 | Y41: 10월 | Z41: 11월 | AA41: 12월 | AC41: 1월
B42: 디지털 영상 | G42: 120478 | H42: 295197 | I42: 118447 | J42: 99054 | K42: 138547 | L42: 108000 | M42: 52110 | N42: 8765 | O42: 940598 | P42: 241210 | Q42: 107282 | R42: 22205 | S42: 78 | T42: 19625 | U42: 3849 | V42: 17028 | W42: 18870 | X42: 347552 | Y42: 324888 | Z42: 132159 | AA42: 1448 | AB42: 1236194 | AE42: 2176792
B43: YouTube | G43: 107441 | H43: 243055 | I43: 112831 | J43: 96261 | K43: 129990 | L43: 105638 | M43: 47352 | N43: 8765 | O43: 851333 | P43: 202623 | Q43: 106537 | R43: 15437 | S43: 78 | T43: 13553 | U43: 3849 | V43: 17028 | W43: 18870 | X43: 274498 | Y43: 225501 | Z43: 129272 | AA43: 1448 | AB43: 1008694 | AE43: 1860027
B44: 네이버 | G44: 262 | H44: 39206 | I44: 2698 | J44: 277 | K44: 5180 | L44: 7 | M44: 979 | O44: 48609 | P44: 38587 | Q44: 745 | R44: 6768 | T44: 6072 | X44: 55436 | Y44: 98225 | Z44: 2371 | AB44: 208204 | AE44: 256813
B45: Tving | G45: 11333 | H45: 12936 | I45: 2918 | J45: 2173 | K45: 3153 | L45: 1535 | M45: 1737 | O45: 35785 | X45: 13586 | AB45: 13586 | AE45: 49371
B46: 다음 | G46: 1256 | M46: 1884 | O46: 3140 | X46: 4032 | Y46: 1162 | Z46: 516 | AB46: 5710 | AE46: 8850
B47: GOMTV | G47: 186 | K47: 163 | L47: 820 | M47: 158 | O47: 1327 | AE47: 1327
B48: Afreecatv | J48: 343 | K48: 61 | O48: 404 | AE48: 404
B49: 네트워크 | C49: 27092 | D49: 28044 | E49: 27203 | F49: 20435 | G49: 189354 | H49: 40145 | I49: 28020 | J49: 1383 | K49: 525 | L49: 9231 | M49: 66 | O49: 371498 | P49: 4002 | Q49: 102142 | R49: 75574 | S49: 4659 | T49: 9140 | U49: 12301 | V49: 33968 | W49: 105167 | X49: 124163 | Y49: 63835 | Z49: 13915 | AA49: 21875 | AB49: 570741 | AC49: 2914 | AD49: 2914 | AE49: 945153
B50: 카카오광고 | C50: 5843 | D50: 6516 | E50: 4068 | G50: 188964 | H50: 39096 | I50: 26064 | O50: 270551 | Q50: 88625 | R50: 13866 | T50: 9074 | U50: 12141 | V50: 16 | W50: 61662 | X50: 96872 | Z50: 8807 | AA50: 19123 | AB50: 310186 | AE50: 580737
B51: 버즈빌 | C51: 21067 | D51: 19707 | E51: 21067 | F51: 19707 | O51: 81548 | X51: 4078 | Y51: 19028 | Z51: 1359 | AB51: 24465 | AC51: 1573 | AD51: 1573 | AE51: 107586
B52: TARGETPICK | R52: 44540 | X52: 21015 | Y52: 42026 | AB52: 107581 | AE52: 107581
B53: NAPDSP | V53: 30644 | W53: 38304 | AB53: 68948 | AE53: 68948
B54: 애드몹 | C54: 182 | D54: 1736 | E54: 1909 | F54: 728 | G54: 390 | H54: 1049 | I54: 1904 | J54: 1383 | K54: 525 | O54: 9806 | P54: 3939 | Q54: 13517 | R54: 1463 | S54: 4659 | U54: 160 | V54: 2360 | W54: 4751 | X54: 182 | AB54: 31031 | AE54: 40837
B55: ADPACKER | R55: 15705 | AB55: 15705 | AE55: 15705
B56: 모비온 | V56: 750 | W56: 450 | X56: 1415 | Y56: 2781 | Z56: 3201 | AA56: 2620 | AB56: 11217 | AC56: 1341 | AD56: 1341 | AE56: 12558
B57: 네트워크 | L57: 8736 | O57: 8736 | AE57: 8736
B58: 오픈마켓 | L58: 495 | M58: 66 | O58: 561 | P58: 63 | T58: 66 | V58: 198 | Z58: 455 | AA58: 132 | AB58: 914 | AE58: 1475
B59: 디지털캠프 | X59: 601 | AB59: 601 | AE59: 601
B60: 크리테오 | E60: 159 | I60: 52 | O60: 211 | AE60: 211
B61: Taboola | D61: 85 | O61: 85 | Z61: 93 | AB61: 93 | AE61: 178
B62: 포털 | C62: 10814 | E62: 2193 | F62: 2193 | G62: 69472 | I62: 4338 | J62: 89381 | L62: 25324 | O62: 203715 | Q62: 46823 | S62: 5094 | T62: 30655 | U62: 121628 | V62: 177795 | W62: 82091 | Y62: 105379 | Z62: 111686 | AA62: 496 | AB62: 681647 | AC62: 20145 | AD62: 20145 | AE62: 905507
B63: 포털 | C63: 10814 | E63: 2193 | F63: 2193 | G63: 69472 | I63: 4338 | J63: 89381 | L63: 23133 | O63: 201524 | Q63: 46823 | S63: 5094 | T63: 30655 | U63: 121628 | V63: 177795 | W63: 81941 | Y63: 104883 | Z63: 111438 | AB63: 680257 | AC63: 19698 | AD63: 19698 | AE63: 901479
B64: 네이버 | L64: 2191 | O64: 2191 | W64: 150 | Y64: 496 | Z64: 248 | AA64: 496 | AB64: 1390 | AC64: 447 | AD64: 447 | AE64: 4028
B65: SNS | C65: 1659 | D65: 1789 | E65: 2258 | F65: 461 | G65: 4577 | J65: 2791 | K65: 62 | M65: 734 | N65: 6614 | O65: 20945 | P65: 2764 | Q65: 9005 | R65: 3274 | S65: 8128 | T65: 62 | U65: 10651 | V65: 5606 | X65: 2564 | Z65: 12829 | AA65: 3831 | AB65: 58714 | AC65: 1717 | AD65: 1717 | AE65: 81376
B66: SNS | C66: 1659 | D66: 1789 | E66: 2258 | F66: 461 | G66: 4577 | J66: 2791 | K66: 62 | M66: 734 | N66: 6614 | O66: 20945 | P66: 2764 | Q66: 9005 | R66: 3274 | S66: 8128 | T66: 62 | U66: 10651 | V66: 5606 | X66: 2564 | Z66: 12829 | AA66: 3831 | AB66: 58714 | AC66: 1717 | AD66: 1717 | AE66: 81376
B67: 총 합계 | C67: 39565 | D67: 29833 | E67: 31654 | F67: 23089 | G67: 383881 | H67: 335342 | I67: 150805 | J67: 192609 | K67: 139134 | L67: 142555 | M67: 52910 | N67: 15379 | O67: 1536756 | P67: 247976 | Q67: 265252 | R67: 101053 | S67: 17959 | T67: 59482 | U67: 148429 | V67: 234397 | W67: 206128 | X67: 474279 | Y67: 494102 | Z67: 270589 | AA67: 27650 | AB67: 2547296 | AC67: 24776 | AD67: 24776 | AE67: 4108828
...

Sheet RAW
A1: 매체 카테고리 | B1: 카테고리 세분화 | C1: 구분 | D1: 광고주 | E1: 브랜드/제품 | F1: 업종(대) | G1: 업종(중) | H1: 업종(소) | I1: 앱/매체 | J1: 매체카테고리/플랫폼 | K1: 게재면 | L1: 플랫폼 | M1: 연 | N1: 월 | O1: 시작일 | P1: 종료일 | Q1: 광고비(천원)
A2: 네트워크 | B2: =IF(L2="-",VLOOKUP(J2,CODE!$B:$D,2,0),L2) -> Taboola | C2: 리서치애드 | D2: 락앤락 | E2: 락앤락 | F2: 가정용품 | G2: 주방용품 | H2: 바이오 용기 | I2: imbc.com | J2: 방송(대)방송국(중) | K2: 연예 | L2: Taboola | M2: =LEFT(O2,2) -> 24 | N2: =MID(O2,4,2) -> 02 | O2: 24.02.15 | P2: 24.02.15 | Q2: 85
A3: =IFERROR(VLOOKUP(B3,CODE!$B:$D,3,0),"-") -> SNS | B3: =IF(L3="-",VLOOKUP(J3,CODE!$B:$D,2,0),L3) -> SNS | C3: 리서치애드 | D3: 락앤락 | E3: 락앤락 | F3: 가정용품 | G3: 주방용품 | H3: 바이오 용기 | I3: facebook.com | J3: 커뮤니티(대)홈페이지(중) | K3: 커뮤니케이션 기타 | L3: - | M3: =LEFT(O3,2) -> 24 | N3: =MID(O3,4,2) -> 03 | O3: 24.03.17 | P3: 24.03.17 | Q3: 62
A4: =IFERROR(VLOOKUP(B4,CODE!$B:$D,3,0),"-") -> SNS | B4: =IF(L4="-",VLOOKUP(J4,CODE!$B:$D,2,0),L4) -> SNS | C4: 리서치애드 | D4: 락앤락 | E4: 락앤락 | F4: 가정용품 | G4: 주방용품 | H4: 바이오 용기 | I4: facebook.com | J4: 커뮤니티(대)홈페이지(중) | K4: 커뮤니케이션 기타 | L4: - | M4: =LEFT(O4,2) -> 24 | N4: =MID(O4,4,2) -> 05 | O4: 24.05.22 | P4: 24.05.22 | Q4: 62
A5: 네트워크 | B5: =IF(L5="-",VLOOKUP(J5,CODE!$B:$D,2,0),L5) -> 크리테오 | C5: 리서치애드 | D5: 락앤락 | E5: 락앤락 | F5: 가정용품 | G5: 주방용품 | H5: 바이오 용기 | I5: tf.co.kr | J5: 신문/잡지(대)스포츠신문(중) | K5: TV | L5: 크리테오 | M5: =LEFT(O5,2) -> 24 | N5: =MID(O5,4,2) -> 03 | O5: 24.03.27 | P5: 24.03.27 | Q5: 26
A6: =IFERROR(VLOOKUP(B6,CODE!$B:$D,3,0),"-") -> SNS | B6: =IF(L6="-",VLOOKUP(J6,CODE!$B:$D,2,0),L6) -> SNS | C6: 리서치애드 | D6: 코렐브랜드 | E6: 코렐 | F6: 가정용품 | G6: 주방용품 | H6: 유리 및 자기그릇 | I6: facebook.com | J6: 커뮤니티(대)홈페이지(중) | K6: 커뮤니케이션 기타 | L6: - | M6: =LEFT(O6,2) -> 24 | N6: =MID(O6,4,2) -> 02 | O6: 24.02.26 | P6: 24.02.26 | Q6: 131
A7: =IFERROR(VLOOKUP(B7,CODE!$B:$D,3,0),"-") -> SNS | B7: =IF(L7="-",VLOOKUP(J7,CODE!$B:$D,2,0),L7) -> SNS | C7: 리서치애드 | D7: 글라스락 | E7: 글라스락 | F7: 가정용품 | G7: 주방용품 | H7: 유리 및 자기그릇 | I7: facebook.com | J7: 커뮤니티(대)홈페이지(중) | K7: 커뮤니케이션 기타 | L7: - | M7: =LEFT(O7,2) -> 24 | N7: =MID(O7,4,2) -> 04 | O7: 24.04.25 | P7: 24.04.25 | Q7: 62
A8: =IFERROR(VLOOKUP(B8,CODE!$B:$D,3,0),"-") -> 포털 | B8: =IF(L8="-",VLOOKUP(J8,CODE!$B:$D,2,0),L8) -> 포털 | C8: 리서치애드 | D8: 이케아코리아 | E8: 이케아 | F8: 가정용품 | G8: 가구류 | H8: 가구류 제품종합 | I8: naver.com | J8: 포털(대)포털(중) | K8: 메인 | L8: - | M8: =LEFT(O8,2) -> 24 | N8: =MID(O8,4,2) -> 01 | O8: 24.01.11 | P8: 24.01.11 | Q8: 10814
A9: =IFERROR(VLOOKUP(B9,CODE!$B:$D,3,0),"-") -> 포털 | B9: =IF(L9="-",VLOOKUP(J9,CODE!$B:$D,2,0),L9) -> 포털 | C9: 리서치애드 | D9: 이케아코리아 | E9: 이케아 | F9: 가정용품 | G9: 가구류 | H9: 가구류 제품종합 | I9: naver.com | J9: 포털(대)포털(중) | K9: 메인 | L9: - | M9: =LEFT(O9,2) -> 24 | N9: =MID(O9,4,2) -> 05 | O9: 24.05.14 | P9: 24.05.14 | Q9: 12027
A10: =IFERROR(VLOOKUP(B10,CODE!$B:$D,3,0),"-") -> SNS | B10: =IF(L10="-",VLOOKUP(J10,CODE!$B:$D,2,0),L10) -> SNS | C10: 리서치애드 | D10: 락앤락 | E10: 락앤락 | F10: 가정용품 | G10: 주방용품 | H10: 바이오 용기 | I10: facebook.com | J10: 커뮤니티(대)홈페이지(중) | K10: 커뮤니케이션 기타 | L10: - | M10: =LEFT(O10,2) -> 24 | N10: =MID(O10,4,2) -> 09 | O10: 24.09.13 | P10: 24.09.13 | Q10: 62
A11: 네트워크 | B11: =IF(L11="-",VLOOKUP(J11,CODE!$B:$D,2,0),L11) -> 크리테오 | C11: 리서치애드 | D11: 락앤락 | E11: 락앤락 | F11: 가정용품 | G11: 주방용품 | H11: 바이오 용기 | I11: MSN | J11: 포털(대)포털(중) | K11: 메인 | L11: 크리테오 | M11: =LEFT(O11,2) -> 24 | N11: =MID(O11,4,2) -> 07 | O11: 24.07.14 | P11: 24.07.14 | Q11: 26
A12: 네트워크 | B12: =IF(L12="-",VLOOKUP(J12,CODE!$B:$D,2,0),L12) -> 크리테오 | C12: 리서치애드 | D12: 락앤락 | E12: 락앤락 | F12: 가정용품 | G12: 주방용품 | H12: 바이오 용기 | I12: tvchosun.com | J12: 방송(대)방송기타(중) | K12: 동영상플레이어 | L12: 크리테오 | M12: =LEFT(O12,2) -> 24 | N12: =MID(O12,4,2) -> 07 | O12: 24.07.13 | P12: 24.07.13 | Q12: 26
A13: =IFERROR(VLOOKUP(B13,CODE!$B:$D,3,0),"-") -> SNS | B13: =IF(L13="-",VLOOKUP(J13,CODE!$B:$D,2,0),L13) -> SNS | C13: 리서치애드 | D13: 코렐브랜드 | E13: 코렐듀라나노 | F13: 가정용품 | G13: 주방용품 | H13: 조리용구 | I13: facebook.com | J13: 커뮤니티(대)홈페이지(중) | K13: 커뮤니케이션 기타 | L13: - | M13: =LEFT(O13,2) -> 24 | N13: =MID(O13,4,2) -> 08 | O13: 24.08.11 | P13: 24.08.11 | Q13: 62
A14: =IFERROR(VLOOKUP(B14,CODE!$B:$D,3,0),"-") -> SNS | B14: =IF(L14="-",VLOOKUP(J14,CODE!$B:$D,2,0),L14) -> SNS | C14: 리서치애드 | D14: 코렐브랜드 | E14: 코렐듀라나노 | F14: 가정용품 | G14: 주방용품 | H14: 조리용구 | I14: facebook.com | J14: 커뮤니티(대)홈페이지(중) | K14: 커뮤니케이션 기타 | L14: - | M14: =LEFT(O14,2) -> 24 | N14: =MID(O14,4,2) -> 08 | O14: 24.08.12 | P14: 24.08.18 | Q14: 432
A15: =IFERROR(VLOOKUP(B15,CODE!$B:$D,3,0),"-") -> SNS | B15: =IF(L15="-",VLOOKUP(J15,CODE!$B:$D,2,0),L15) -> SNS | C15: 리서치애드 | D15: 코렐브랜드 | E15: 코렐듀라나노 | F15: 가정용품 | G15: 주방용품 | H15: 조리용구 | I15: facebook.com | J15: 커뮤니티(대)홈페이지(중) | K15: 커뮤니케이션 기타 | L15: - | M15: =LEFT(O15,2) -> 24 | N15: =MID(O15,4,2) -> 08 | O15: 24.08.22 | P15: 24.08.22 | Q15: 62
A16: =IFERROR(VLOOKUP(B16,CODE!$B:$D,3,0),"-") -> SNS | B16: =IF(L16="-",VLOOKUP(J16,CODE!$B:$D,2,0),L16) -> SNS | C16: 리서치애드 | D16: 코렐브랜드 | E16: 코렐듀라나노 | F16: 가정용품 | G16: 주방용품 | H16: 조리용구 | I16: facebook.com | J16: 커뮤니티(대)홈페이지(중) | K16: 커뮤니케이션 기타 | L16: - | M16: =LEFT(O16,2) -> 24 | N16: =MID(O16,4,2) -> 12 | O16: 24.12.03 | P16: 24.12.04 | Q16: 123
A17: =IFERROR(VLOOKUP(B17,CODE!$B:$D,3,0),"-") -> SNS | B17: =IF(L17="-",VLOOKUP(J17,CODE!$B:$D,2,0),L17) -> SNS | C17: 리서치애드 | D17: 코렐브랜드 | E17: 코렐듀라나노 | F17: 가정용품 | G17: 주방용품 | H17: 조리용구 | I17: facebook.com | J17: 커뮤니티(대)홈페이지(중) | K17: 커뮤니케이션 기타 | L17: - | M17: =LEFT(O17,2) -> 24 | N17: =MID(O17,4,2) -> 12 | O17: 24.12.09 | P17: 24.12.10 | Q17: 3241
A18: =IFERROR(VLOOKUP(B18,CODE!$B:$D,3,0),"-") -> 포털 | B18: =IF(L18="-",VLOOKUP(J18,CODE!$B:$D,2,0),L18) -> 포털 | C18: 리서치애드 | D18: 글라스락 | E18: 글라스락 | F18: 가정용품 | G18: 주방용품 | H18: 유리 및 자기그릇 | I18: naver.com | J18: 포털(대)포털(중) | K18: 뉴스 | L18: - | M18: =LEFT(O18,2) -> 24 | N18: =MID(O18,4,2) -> 08 | O18: 24.08.13 | P18: 24.08.18 | Q18: 186
A19: =IFERROR(VLOOKUP(B19,CODE!$B:$D,3,0),"-") -> 포털 | B19: =IF(L19="-",VLOOKUP(J19,CODE!$B:$D,2,0),L19) -> 포털 | C19: 리서치애드 | D19: 이케아코리아 | E19: 이케아 | F19: 가정용품 | G19: 가구류 | H19: 가구류 제품종합 | I19: naver.com | J19: 포털(대)포털(중) | K19: 메인 | L19: - | M19: =LEFT(O19,2) -> 24 | N19: =MID(O19,4,2) -> 08 | O19: 24.08.30 | P19: 24.08.30 | Q19: 19782
A20: 네트워크 | B20: =IF(L20="-",VLOOKUP(J20,CODE!$B:$D,2,0),L20) -> 네트워크 | C20: 리서치애드 | D20: 이케아코리아 | E20: 이케아 | F20: 가정용품 | G20: 가구류 | H20: 가구류 제품종합 | I20: jobkorea.co.kr | J20: 생활정보(대)구인/구직(중) | K20: 메인 | L20: 네트워크 | M20: =LEFT(O20,2) -> 24 | N20: =MID(O20,4,2) -> 10 | O20: 24.10.15 | P20: 24.10.20 | Q20: 2849
A21: 네트워크 | B21: =IF(L21="-",VLOOKUP(J21,CODE!$B:$D,2,0),L21) -> 네트워크 | C21: 리서치애드 | D21: 이케아코리아 | E21: 이케아 | F21: 가정용품 | G21: 가구류 | H21: 가구류 제품종합 | I21: jobkorea.co.kr | J21: 생활정보(대)구인/구직(중) | K21: 메인 | L21: 네트워크 | M21: =LEFT(O21,2) -> 24 | N21: =MID(O21,4,2) -> 10 | O21: 24.10.21 | P21: 24.10.24 | Q21: 1899
A22: 네트워크 | B22: =IF(L22="-",VLOOKUP(J22,CODE!$B:$D,2,0),L22) -> 네트워크 | C22: 리서치애드 | D22: 이케아코리아 | E22: 이케아 | F22: 가정용품 | G22: 가구류 | H22: 가구류 제품종합 | I22: jobkorea.co.kr | J22: 생활정보(대)구인/구직(중) | K22: 채용정보검색 | L22: 네트워크 | M22: =LEFT(O22,2) -> 24 | N22: =MID(O22,4,2) -> 10 | O22: 24.10.15 | P22: 24.10.20 | Q22: 1141
A23: 포털 | B23: 네이버 | C23: 리서치애드 | D23: 이케아코리아 | E23: 이케아 | F23: 가정용품 | G23: 가구류 | H23: 가구류 제품종합 | I23: jobkorea.co.kr | J23: 생활정보(대)구인/구직(중) | K23: 채용정보검색 | L23: - | M23: =LEFT(O23,2) -> 24 | N23: =MID(O23,4,2) -> 10 | O23: 24.10.21 | P23: 24.10.24 | Q23: 761
A24: 포털 | B24: 네이버 | C24: 리서치애드 | D24: 이케아코리아 | E24: 이케아 | F24: 가정용품 | G24: 가구류 | H24: 가구류 제품종합 | I24: jobkorea.co.kr | J24: 생활정보(대)구인/구직(중) | K24: 채용정보검색 | L24: - | M24: =LEFT(O24,2) -> 24 | N24: =MID(O24,4,2) -> 10 | O24: 24.10.15 | P24: 24.10.20 | Q24: 858
A25: 포털 | B25: 네이버 | C25: 리서치애드 | D25: 이케아코리아 | E25: 이케아 | F25: 가정용품 | G25: 가구류 | H25: 가구류 제품종합 | I25: jobkorea.co.kr | J25: 생활정보(대)구인/구직(중) | K25: 채용정보검색 | L25: - | M25: =LEFT(O25,2) -> 24 | N25: =MID(O25,4,2) -> 10 | O25: 24.10.21 | P25: 24.10.24 | Q25: 572
A26: =IFERROR(VLOOKUP(B26,CODE!$B:$D,3,0),"-") -> SNS | B26: =IF(L26="-",VLOOKUP(J26,CODE!$B:$D,2,0),L26) -> SNS | C26: 리서치애드 | D26: 락앤락 | E26: 락앤락 | F26: 가정용품 | G26: 주방용품 | H26: 바이오 용기 | I26: facebook.com | J26: 커뮤니티(대)홈페이지(중) | K26: 커뮤니케이션 기타 | L26: - | M26: =LEFT(O26,2) -> 25 | N26: =MID(O26,4,2) -> 01 | O26: 25.01.23 | P26: 25.01.23 | Q26: 62
A27: =IFERROR(VLOOKUP(B27,CODE!$B:$D,3,0),"-") -> 네트워크 | B27: =IF(L27="-",VLOOKUP(J27,CODE!$B:$D,2,0),L27) -> 오픈마켓 | C27: 리서치애드 | D27: 락앤락 | E27: 락앤락 | F27: 가정용품 | G27: 주방용품 | H27: 바이오 용기 | I27: 11st.co.kr | J27: 생활정보(대)쇼핑/가격정보(중) | K27: 식품 | L27: - | M27: =LEFT(O27,2) -> 25 | N27: =MID(O27,4,2) -> 01 | O27: 25.01.10 | P27: 25.01.12 | Q27: 47
A28: =IFERROR(VLOOKUP(B28,CODE!$B:$D,3,0),"-") -> 네트워크 | B28: =IF(L28="-",VLOOKUP(J28,CODE!$B:$D,2,0),L28) -> 오픈마켓 | C28: 리서치애드 | D28: 락앤락 | E28: 락앤락 | F28: 가정용품 | G28: 주방용품 | H28: 바이오 용기 | I28: 11st.co.kr | J28: 생활정보(대)쇼핑/가격정보(중) | K28: 식품 | L28: - | M28: =LEFT(O28,2) -> 25 | N28: =MID(O28,4,2) -> 01 | O28: 25.01.13 | P28: 25.01.13 | Q28: 16
A29: =IFERROR(VLOOKUP(B29,CODE!$B:$D,3,0),"-") -> SNS | B29: =IF(L29="-",VLOOKUP(J29,CODE!$B:$D,2,0),L29) -> SNS | C29: 리서치애드 | D29: 락앤락 | E29: 락앤락4in1멀티쿠커 | F29: 가정용 전기전자 | G29: 주방용 전기전자 | H29: 주방용 전기전자 기타 | I29: facebook.com | J29: 커뮤니티(대)홈페이지(중) | K29: 커뮤니케이션 기타 | L29: - | M29: =LEFT(O29,2) -> 25 | N29: =MID(O29,4,2) -> 05 | O29: 25.05.25 | P29: 25.05.25 | Q29: 62
A30: =IFERROR(VLOOKUP(B30,CODE!$B:$D,3,0),"-") -> SNS | B30: =IF(L30="-",VLOOKUP(J30,CODE!$B:$D,2,0),L30) -> SNS | C30: 리서치애드 | D30: 코렐브랜드 | E30: 코렐듀라나노 | F30: 가정용품 | G30: 주방용품 | H30: 조리용구 | I30: facebook.com | J30: 커뮤니티(대)홈페이지(중) | K30: 커뮤니케이션 기타 | L30: - | M30: =LEFT(O30,2) -> 25 | N30: =MID(O30,4,2) -> 01 | O30: 25.01.25 | P30: 25.01.26 | Q30: 123
A31: =IFERROR(VLOOKUP(B31,CODE!$B:$D,3,0),"-") -> SNS | B31: =IF(L31="-",VLOOKUP(J31,CODE!$B:$D,2,0),L31) -> SNS | C31: 리서치애드 | D31: 코렐브랜드 | E31: 코렐듀라나노 | F31: 가정용품 | G31: 주방용품 | H31: 조리용구 | I31: facebook.com | J31: 커뮤니티(대)홈페이지(중) | K31: 커뮤니케이션 기타 | L31: - | M31: =LEFT(O31,2) -> 25 | N31: =MID(O31,4,2) -> 01 | O31: 25.01.30 | P31: 25.01.31 | Q31: 123
A32: =IFERROR(VLOOKUP(B32,CODE!$B:$D,3,0),"-") -> SNS | B32: =IF(L32="-",VLOOKUP(J32,CODE!$B:$D,2,0),L32) -> SNS | C32: 리서치애드 | D32: 글라스락 | E32: 글라스락 | F32: 가정용품 | G32: 주방용품 | H32: 유리 및 자기그릇 | I32: facebook.com | J32: 커뮤니티(대)홈페이지(중) | K32: 동영상플레이어 | L32: - | M32: =LEFT(O32,2) -> 25 | N32: =MID(O32,4,2) -> 04 | O32: 25.04.16 | P32: 25.04.16 | Q32: 62
A33: =IFERROR(VLOOKUP(B33,CODE!$B:$D,3,0),"-") -> 포털 | B33: =IF(L33="-",VLOOKUP(J33,CODE!$B:$D,2,0),L33) -> 포털 | C33: 리서치애드 | D33: 이케아코리아 | E33: 이케아 | F33: 가정용품 | G33: 가구류 | H33: 가구류 제품종합 | I33: naver.com | J33: 포털(대)포털(중) | K33: 메인 | L33: - | M33: =LEFT(O33,2) -> 25 | N33: =MID(O33,4,2) -> 02 | O33: 25.02.14 | P33: 25.02.14 | Q33: 44276
A34: =IFERROR(VLOOKUP(B34,CODE!$B:$D,3,0),"-") -> 포털 | B34: =IF(L34="-",VLOOKUP(J34,CODE!$B:$D,2,0),L34) -> 포털 | C34: 리서치애드 | D34: 이케아코리아 | E34: 이케아 | F34: 가정용품 | G34: 가구류 | H34: 가구류 제품종합 | I34: naver.com | J34: 포털(대)포털(중) | K34: 메인 | L34: - | M34: =LEFT(O34,2) -> 25 | N34: =MID(O34,4,2) -> 06 | O34: 25.06.19 | P34: 25.06.19 | Q34: 44993
A35: =IFERROR(VLOOKUP(B35,CODE!$B:$D,3,0),"-") -> 포털 | B35: =IF(L35="-",VLOOKUP(J35,CODE!$B:$D,2,0),L35) -> 포털 | C35: 리서치애드 | D35: 락앤락 | E35: 락앤락 | F35: 가정용품 | G35: 주방용품 | H35: 바이오 용기 | I35: naver.com | J35: 포털(대)포털(중) | K35: 뉴스 | L35: - | M35: =LEFT(O35,2) -> 26 | N35: =MID(O35,4,2) -> 01 | O35: 26.01.06 | P35: 26.01.06 | Q35: 31
A36: =IFERROR(VLOOKUP(B36,CODE!$B:$D,3,0),"-") -> SNS | B36: =IF(L36="-",VLOOKUP(J36,CODE!$B:$D,2,0),L36) -> SNS | C36: 리서치애드 | D36: 락앤락 | E36: 락앤락 | F36: 가정용품 | G36: 주방용품 | H36: 바이오 용기 | I36: facebook.com | J36: 커뮤니티(대)홈페이지(중) | K36: 커뮤니케이션 기타 | L36: - | M36: =LEFT(O36,2) -> 26 | N36: =MID(O36,4,2) -> 01 | O36: 26.01.02 | P36: 26.01.02 | Q36: 62
A37: =IFERROR(VLOOKUP(B37,CODE!$B:$D,3,0),"-") -> SNS | B37: =IF(L37="-",VLOOKUP(J37,CODE!$B:$D,2,0),L37) -> SNS | C37: 리서치애드 | D37: 락앤락 | E37: 락앤락 | F37: 가정용품 | G37: 주방용품 | H37: 바이오 용기 | I37: facebook.com | J37: 커뮤니티(대)홈페이지(중) | K37: 커뮤니케이션 기타 | L37: - | M37: =LEFT(O37,2) -> 25 | N37: =MID(O37,4,2) -> 11 | O37: 25.11.20 | P37: 25.11.23 | Q37: 5168
... A42: =IFERROR(VLOOKUP(B42,CODE!$B:$D,3,0),"-") -> 네트워크 | B42: =IF(L42="-",VLOOKUP(J42,CODE!$B:$D,2,0),L42) -> 모비온 | C42: 리서치애드 | D42: 글라스락 | E42: 글라스락 | F42: 가정용품 | G42: 주방용품 | H42: 유리 및 자기그릇 | I42: nate.com | J42: 포털(대)포털(중) | K42: 뉴스 | L42: 모비온 | M42: =LEFT(O42,2) -> 25 | N42: =MID(O42,4,2) -> 10 | O42: 25.10.24 | P42: 25.10.24 | Q42: 124
A43: 포털 | B43: 네이버 | C43: 리서치애드 | D43: 글라스락 | E43: 글라스락 | F43: 가정용품 | G43: 주방용품 | H43: 유리 및 자기그릇 | I43: nate.com | J43: 포털(대)포털(중) | K43: 연예 | L43: 모비온 | M43: =LEFT(O43,2) -> 25 | N43: =MID(O43,4,2) -> 12 | O43: 25.12.23 | P43: 25.12.23 | Q43: 124
A44: 포털 | B44: 네이버 | C44: 리서치애드 | D44: 글라스락 | E44: 글라스락 | F44: 가정용품 | G44: 주방용품 | H44: 유리 및 자기그릇 | I44: chosun.com | J44: 신문/잡지(대)종합일간지(중) | K44: 스포츠 | L44: 모비온 | M44: =LEFT(O44,2) -> 25 | N44: =MID(O44,4,2) -> 10 | O44: 25.10.22 | P44: 25.10.22 | Q44: 124
...

Sheet ADEX CODE
B2: Year | C2: Month | D2: Ad_Spending | E2: 시작일 | F2: 종료일 | G2: Spending(천원)
B3: 2024년 | C3: 12 | D3: 8765000 | E3: =MID(B3,3,2)&"."&IF(C3<10,"0"&C3,C3) -> 24.12 | F3: =MID(B3,3,2)&"."&IF(C3<10,"0"&C3,C3) -> 24.12 | G3: =TEXT(D3,"#,###,") -> 8,765 | I3: 24.12 | J3: 24.12 | K3: 8765
B4: 2024년 | C4: 11 | D4: 1884000 | E4: =MID(B4,3,2)&"."&IF(C4<10,"0"&C4,C4) -> 24.11 | F4: =MID(B4,3,2)&"."&IF(C4<10,"0"&C4,C4) -> 24.11 | G4: =TEXT(D4,"#,###,") -> 1,884 | I4: 24.11 | J4: 24.11 | K4: 1884
B5: 2024년 | C5: 11 | D5: 158000 | E5: =MID(B5,3,2)&"."&IF(C5<10,"0"&C5,C5) -> 24.11 | F5: =MID(B5,3,2)&"."&IF(C5<10,"0"&C5,C5) -> 24.11 | G5: =TEXT(D5,"#,###,") -> 158 | I5: 24.11 | J5: 24.11 | K5: 158
B6: 2024년 | C6: 11 | D6: 47352000 | E6: =MID(B6,3,2)&"."&IF(C6<10,"0"&C6,C6) -> 24.11 | F6: =MID(B6,3,2)&"."&IF(C6<10,"0"&C6,C6) -> 24.11 | G6: =TEXT(D6,"#,###,") -> 47,352 | I6: 24.11 | J6: 24.11 | K6: 47352
B7: 2024년 | C7: 11 | D7: 1737000 | E7: =MID(B7,3,2)&"."&IF(C7<10,"0"&C7,C7) -> 24.11 | F7: =MID(B7,3,2)&"."&IF(C7<10,"0"&C7,C7) -> 24.11 | G7: =TEXT(D7,"#,###,") -> 1,737 | I7: 24.11 | J7: 24.11 | K7: 1737
B8: 2024년 | C8: 11 | D8: 979000 | E8: =MID(B8,3,2)&"."&IF(C8<10,"0"&C8,C8) -> 24.11 | F8: =MID(B8,3,2)&"."&IF(C8<10,"0"&C8,C8) -> 24.11 | G8: =TEXT(D8,"#,###,") -> 979 | I8: 24.11 | J8: 24.11 | K8: 979
B9: 2024년 | C9: 10 | D9: 102913000 | E9: =MID(B9,3,2)&"."&IF(C9<10,"0"&C9,C9) -> 24.10 | F9: =MID(B9,3,2)&"."&IF(C9<10,"0"&C9,C9) -> 24.10 | G9: =TEXT(D9,"#,###,") -> 102,913 | I9: 24.1 | J9: 24.1 | K9: 102913
B10: 2024년 | C10: 10 | D10: 1535000 | E10: =MID(B10,3,2)&"."&IF(C10<10,"0"&C10,C10) -> 24.10 | F10: =MID(B10,3,2)&"."&IF(C10<10,"0"&C10,C10) -> 24.10 | G10: =TEXT(D10,"#,###,") -> 1,535 | I10: 24.1 | J10: 24.1 | K10: 1535
B11: 2024년 | C11: 10 | D11: 7000 | E11: =MID(B11,3,2)&"."&IF(C11<10,"0"&C11,C11) -> 24.10 | F11: =MID(B11,3,2)&"."&IF(C11<10,"0"&C11,C11) -> 24.10 | G11: =TEXT(D11,"#,###,") -> 7 | I11: 24.1 | J11: 24.1 | K11: 7
B12: 2024년 | C12: 10 | D12: 820000 | E12: =MID(B12,3,2)&"."&IF(C12<10,"0"&C12,C12) -> 24.10 | F12: =MID(B12,3,2)&"."&IF(C12<10,"0"&C12,C12) -> 24.10 | G12: =TEXT(D12,"#,###,") -> 820 | I12: 24.1 | J12: 24.1 | K12: 820
B13: 2024년 | C13: 10 | D13: 2725000 | E13: =MID(B13,3,2)&"."&IF(C13<10,"0"&C13,C13) -> 24.10 | F13: =MID(B13,3,2)&"."&IF(C13<10,"0"&C13,C13) -> 24.10 | G13: =TEXT(D13,"#,###,") -> 2,725 | I13: 24.1 | J13: 24.1 | K13: 2725
B14: 2024년 | C14: 9 | D14: 12018000 | E14: =MID(B14,3,2)&"."&IF(C14<10,"0"&C14,C14) -> 24.09 | F14: =MID(B14,3,2)&"."&IF(C14<10,"0"&C14,C14) -> 24.09 | G14: =TEXT(D14,"#,###,") -> 12,018 | I14: 24.09 | J14: 24.09 | K14: 12018
... B87: 2025년 | C87: 1 | D87: 8149000 | E87: =MID(B87,3,2)&"."&IF(C87<10,"0"&C87,C87) -> 25.01 | F87: =MID(B87,3,2)&"."&IF(C87<10,"0"&C87,C87) -> 25.01 | G87: =TEXT(D87,"#,###,") -> 8,149 | I87: 25.01 | J87: 25.01 | K87: 8149
E88: =MID(B88,3,2)&"."&IF(C88<10,"0"&C88,C88) -> .0 | F88: =MID(B88,3,2)&"."&IF(C88<10,"0"&C88,C88) -> .0 | G88: =TEXT(D88,"#,###,")
E89: =MID(B89,3,2)&"."&IF(C89<10,"0"&C89,C89) -> .0 | F89: =MID(B89,3,2)&"."&IF(C89<10,"0"&C89,C89) -> .0 | G89: =TEXT(D89,"#,###,")
E90: =MID(B90,3,2)&"."&IF(C90<10,"0"&C90,C90) -> .0 | F90: =MID(B90,3,2)&"."&IF(C90<10,"0"&C90,C90) -> .0 | G90: =TEXT(D90,"#,###,")
E91: =MID(B91,3,2)&"."&IF(C91<10,"0"&C91,C91) -> .0 | F91: =MID(B91,3,2)&"."&IF(C91<10,"0"&C91,C91) -> .0 | G91: =TEXT(D91,"#,###,")
E92: =MID(B92,3,2)&"."&IF(C92<10,"0"&C92,C92) -> .0 | F92: =MID(B92,3,2)&"."&IF(C92<10,"0"&C92,C92) -> .0 | G92: =TEXT(D92,"#,###,")
E93: =MID(B93,3,2)&"."&IF(C93<10,"0"&C93,C93) -> .0 | F93: =MID(B93,3,2)&"."&IF(C93<10,"0"&C93,C93) -> .0 | G93: =TEXT(D93,"#,###,")
E94: =MID(B94,3,2)&"."&IF(C94<10,"0"&C94,C94) -> .0 | F94: =MID(B94,3,2)&"."&IF(C94<10,"0"&C94,C94) -> .0 | G94: =TEXT(D94,"#,###,")
E95: =MID(B95,3,2)&"."&IF(C95<10,"0"&C95,C95) -> .0 | F95: =MID(B95,3,2)&"."&IF(C95<10,"0"&C95,C95) -> .0 | G95: =TEXT(D95,"#,###,")
E96: =MID(B96,3,2)&"."&IF(C96<10,"0"&C96,C96) -> .0 | F96: =MID(B96,3,2)&"."&IF(C96<10,"0"&C96,C96) -> .0 | G96: =TEXT(D96,"#,###,")
E97: =MID(B97,3,2)&"."&IF(C97<10,"0"&C97,C97) -> .0 | F97: =MID(B97,3,2)&"."&IF(C97<10,"0"&C97,C97) -> .0 | G97: =TEXT(D97,"#,###,")
E98: =MID(B98,3,2)&"."&IF(C98<10,"0"&C98,C98) -> .0 | F98: =MID(B98,3,2)&"."&IF(C98<10,"0"&C98,C98) -> .0 | G98: =TEXT(D98,"#,###,")
E99: =MID(B99,3,2)&"."&IF(C99<10,"0"&C99,C99) -> .0 | F99: =MID(B99,3,2)&"."&IF(C99<10,"0"&C99,C99) -> .0 | G99: =TEXT(D99,"#,###,")
... E4683: =MID(B4683,3,2)&"."&IF(C4683<10,"0"&C4683,C4683) -> .0 | F4683: =MID(B4683,3,2)&"."&IF(C4683<10,"0"&C4683,C4683) -> .0 | G4683: =TEXT(D4683,"#,###,")

Sheet CODE
B2: 매체카테고리/구분 | C2: 카테고리 | D2: 매체 카테고리 | F2: 확인용 PV | I2: 제품명 | J2: 브랜드명
B3: 디지털동영상 | C3: 디지털 영상 | D3: 디지털 영상 | F3: 행 레이블 | G3: 합계 : 광고비(천원) | I3: 아이더스에프앤비푸라닭치킨 | J3: 푸라닭
B4: 모바일(대)모바일기타(중) | C4: 네트워크 | D4: 네트워크 | F4: 아이더스에프앤비푸라닭치킨 | G4: 16539647 | I4: 장스푸드60계치킨 | J4: 60계치킨
B5: 생활정보(대)쇼핑/가격정보(중) | C5: 오픈마켓 | D5: 네트워크 | F5: 장스푸드60계치킨 | G5: 13996848 | I5: 자담치킨 | J5: 자담치킨
B6: 신문 | C6: 신문 | D6: 인쇄 | F6: 자담치킨 | G6: 13669017 | I6: BHC | J6: BHC
B7: 신문/잡지(대)경제신문(중) | C7: 언론사 | D7: 네트워크 | F7: BHC | G7: 12315508 | I7: 네네치킨 | J7: 네네치킨
B8: 신문/잡지(대)스포츠신문(중) | C8: 언론사 | D8: 네트워크 | F8: 네네치킨 | G8: 5102301 | I8: 호식이두마리치킨 | J8: 호식이두마리치킨
B9: 신문/잡지(대)신문/잡지 기타(중) | C9: 언론사 | D9: 네트워크 | F9: 호식이두마리치킨 | G9: 4949209 | I9: 노랑푸드노랑통닭 | J9: 노랑통닭
B10: 신문/잡지(대)온라인뉴스(중) | C10: 언론사 | D10: 네트워크 | F10: 노랑푸드노랑통닭 | G10: 3561160 | I10: 멕시카나치킨* | J10: 멕시카나
B11: 신문/잡지(대)종합일간지(중) | C11: 언론사 | D11: 네트워크 | F11: 멕시카나치킨* | G11: 3520321 | I11: 코리아델로스치킨매니아 | J11: 치킨매니아
B12: 엔터테인먼트(대)엔터테인먼트 기타(중) | C12: 디지털 영상 | D12: 디지털 영상 | F12: 코리아델로스치킨매니아 | G12: 2797825 | I12: 교촌치킨 | J12: 교촌치킨
B13: 잡지 | C13: 잡지 | D13: 인쇄 | F13: 교촌치킨 | G13: 1517333 | I13: 티앤비코리아누구나홀딱반한닭 | J13: 누구나홀딱반한닭
B14: 종편 | C14: 종편 | D14: 인쇄 | F14: 티앤비코리아누구나홀딱반한닭 | G14: 1318590 | I14: 꼬꼬에프앤비맛닭꼬치킨 | J14: 맛닭꼬치킨
B15: 지상파 | C15: 지상파 | D15: 방송 | F15: 꼬꼬에프앤비맛닭꼬치킨 | G15: 1273100 | I15: 노상치킨 | J15: 노상치킨
... B42: 신문/잡지(대)IT관련 뉴스(중) | C42: 언론사 | D42: 네트워크 | F42: 총합계 | G42: 86774638 | I42: 노랑강정 | J42: 노랑강정
B43: YouTube | C43: 디지털 영상 | D43: 디지털 영상
B44: 네이버 | C44: 디지털 영상 | D44: 디지털 영상
B45: Tving | C45: 디지털 영상 | D45: 디지털 영상
B46: 기타 | C46: 디지털 영상 | D46: 디지털 영상
B47: GDN | C47: 네트워크 | D47: 네트워크
B48: ADPACKER | C48: 네트워크 | D48: 네트워크
B49: Dable | C49: 네트워크 | D49: 네트워크
B50: NAPDSP | C50: 네트워크 | D50: 네트워크
B51: MOLOCO | C51: 네트워크 | D51: 네트워크
B52: APPIER | C52: 네트워크 | D52: 네트워크
B53: 다음 | C53: 디지털 영상 | D53: 디지털 영상
